<?xml version="1.0" encoding="utf-8" ?>
<!-- =================================================================================== -->
<!-- |    This document was autogenerated by xacro from ./src/fanuc_lrmate200id_support/urdf/fanuc_lrmate200id_include.xacro | -->
<!-- |    EDITING THIS FILE BY HAND IS NOT RECOMMENDED                                 | -->
<!-- =================================================================================== -->
<robot name="fanuc_lrmate200id">
    <!-- links: main serial chain -->
    <link name="base_link">
        <visual>
            <origin rpy="0 0 0" xyz="0 0 0" />
            <geometry>
                <mesh filename="package://fanuc_lrmate200id_support/meshes/lrmate200id/visual/base_link.stl" />
            </geometry>
            <material name="">
                <color rgba="0.278431372549 0.278431372549 0.278431372549 1.0" />
            </material>
        </visual>
        <collision>
            <origin rpy="0 0 0" xyz="0 0 0" />
            <geometry>
                <mesh filename="package://fanuc_lrmate200id_support/meshes/lrmate200id/collision/base_link.stl" />
            </geometry>
        </collision>
        
<inertial>
            <mass value="4" />
            <origin rpy="0 0 0" xyz="0 0 0" />
            <inertia ixx="0.0216667" ixy="0" ixz="0" iyy="0.0216667" iyz="0" izz="0.0240667" />
        </inertial>

    </link>
    <link name="link_1">
        <visual>
            <origin rpy="0 0 0" xyz="0 0 0" />
            <geometry>
                <mesh filename="package://fanuc_lrmate200id_support/meshes/lrmate200id/visual/link_1.stl" />
            </geometry>
            <material name="">
                <color rgba="0.96 0.76 0.13 1.0" />
            </material>
        </visual>
        <collision>
            <origin rpy="0 0 0" xyz="0 0 0" />
            <geometry>
                <mesh filename="package://fanuc_lrmate200id_support/meshes/lrmate200id/collision/link_1.stl" />
            </geometry>
        </collision>
        
<inertial>
            <mass value="4" />
            <origin rpy="0 0 0" xyz="0 0 0" />
            <inertia ixx="0.0322667" ixy="0" ixz="0" iyy="0.0226667" iyz="0" izz="0.0226667" />
        </inertial>

    </link>
    <link name="link_2">
        <visual>
            <origin rpy="0 0 0" xyz="0 0 0" />
            <geometry>
                <mesh filename="package://fanuc_lrmate200id_support/meshes/lrmate200id/visual/link_2.stl" />
            </geometry>
            <material name="">
                <color rgba="0.96 0.76 0.13 1.0" />
            </material>
        </visual>
        <collision>
            <origin rpy="0 0 0" xyz="0 0 0" />
            <geometry>
                <mesh filename="package://fanuc_lrmate200id_support/meshes/lrmate200id/collision/link_2.stl" />
            </geometry>
        </collision>
        
<inertial>
            <mass value="5" />
            <origin rpy="0 0 0" xyz="0 0 0" />
            <inertia ixx="0.0973333" ixy="0" ixz="0" iyy="0.0888333" iyz="0" izz="0.0248333" />
        </inertial>

    </link>
    <link name="link_3">
        <visual>
            <origin rpy="0 0 0" xyz="0 0 0" />
            <geometry>
                <mesh filename="package://fanuc_lrmate200id_support/meshes/lrmate200id/visual/link_3.stl" />
            </geometry>
            <material name="">
                <color rgba="0.96 0.76 0.13 1.0" />
            </material>
        </visual>
        <collision>
            <origin rpy="0 0 0" xyz="0 0 0" />
            <geometry>
                <mesh filename="package://fanuc_lrmate200id_support/meshes/lrmate200id/collision/link_3.stl" />
            </geometry>
        </collision>
        
<inertial>
            <mass value="4" />
            <origin rpy="0 0 0" xyz="0 0 0" />
            <inertia ixx="0.0104333" ixy="0" ixz="0" iyy="0.0121667" iyz="0" izz="0.0113333" />
        </inertial>

    </link>
    <link name="link_4">
        <visual>
            <origin rpy="0 0 0" xyz="0 0 0" />
            <geometry>
                <mesh filename="package://fanuc_lrmate200id_support/meshes/lrmate200id/visual/link_4.stl" />
            </geometry>
            <material name="">
                <color rgba="0.96 0.76 0.13 1.0" />
            </material>
        </visual>
        <collision>
            <origin rpy="0 0 0" xyz="0 0 0" />
            <geometry>
                <mesh filename="package://fanuc_lrmate200id_support/meshes/lrmate200id/collision/link_4.stl" />
            </geometry>
        </collision>
        
<inertial>
            <mass value="5" />
            <origin rpy="0 0 0" xyz="0 0 0" />
            <inertia ixx="0.00833333" ixy="0" ixz="0" iyy="0.0368333" iyz="0" izz="0.0368333" />
        </inertial>

    </link>
    <link name="link_5">
        <visual>
            <origin rpy="0 0 0" xyz="0 0 0" />
            <geometry>
                <mesh filename="package://fanuc_lrmate200id_support/meshes/lrmate200id/visual/link_5.stl" />
            </geometry>
            <material name="">
                <color rgba="0.96 0.76 0.13 1.0" />
            </material>
        </visual>
        <collision>
            <origin rpy="0 0 0" xyz="0 0 0" />
            <geometry>
                <mesh filename="package://fanuc_lrmate200id_support/meshes/lrmate200id/collision/link_5.stl" />
            </geometry>
        </collision>
        
<inertial>
            <mass value="1.5" />
            <origin rpy="0 0 0" xyz="0 0 0" />
            <inertia ixx="0.0018125" ixy="0" ixz="0" iyy="0.0023125" iyz="0" izz="0.002525" />
        </inertial>

    </link>
    <link name="link_6">
        <visual>
            <origin rpy="0 0 0" xyz="-0.057 0 0" />
            <geometry>
                <mesh filename="package://fanuc_lrmate200id_support/meshes/lrmate200id/visual/link_6.stl" />
            </geometry>
            <material name="">
                <color rgba="0.15 0.15 0.15 1.0" />
            </material>
        </visual>
        <collision>
            <origin rpy="0 0 0" xyz="0 0 0" />
            <geometry>
                <mesh filename="package://fanuc_lrmate200id_support/meshes/lrmate200id/collision/link_6.stl" />
            </geometry>
        </collision>
        
<inertial>
            <mass value="0.25" />
            <origin rpy="0 0 0" xyz="0 0 0" />
            <inertia ixx="6.66666e-05" ixy="0" ixz="0" iyy="3.54167e-05" iyz="0" izz="3.54167e-05" />
        </inertial>

    </link>
    <link name="flange">
        <visual>
            <origin rpy="0 0 0" xyz="0 0 0" />
            <geometry>
                <mesh filename="package://fanuc_lrmate200id_support/meshes/lrmate200id/visual/gripper.stl" scale="0.001 0.001 0.001" />
            </geometry>
            <material name="">
                <color rgba="0.75 0.75 0.75 1.0" />
            </material>
        </visual>
        <collision>
            <origin rpy="0 0 0" xyz="0 0 0" />
            <geometry>
                <mesh filename="package://fanuc_lrmate200id_support/meshes/lrmate200id/collision/gripper.stl" scale="0.001 0.001 0.001" />
            </geometry>
        </collision>
        
<inertial>
            <mass value="0.1" />
            <origin rpy="0 0 0" xyz="0 0 0" />
            <inertia ixx="6e-06" ixy="0" ixz="0" iyy="6e-06" iyz="0" izz="6e-06" />
        </inertial>

    </link>
    <link name="left_finger">
        <visual>
            <origin rpy="0 0 0" xyz="0 0 0" />
            <geometry>
                <mesh filename="package://fanuc_lrmate200id_support/meshes/lrmate200id/visual/left_finger.stl" scale="0.001 0.001 0.001" />
            </geometry>
            <material name="">
                <color rgba="0.75 0.75 0.75 1.0" />
            </material>
        </visual>
        <collision>
            <origin rpy="0 0 0" xyz="0 0 0" />
            <geometry>
                <mesh filename="package://fanuc_lrmate200id_support/meshes/lrmate200id/collision/left_finger.stl" scale="0.001 0.001 0.001" />
            </geometry>
        </collision>
        
<inertial>
            <mass value="0.01" />
            <origin rpy="0 0 0" xyz="0 0 0" />
            <inertia ixx="6e-06" ixy="0" ixz="0" iyy="6e-06" iyz="0" izz="6e-06" />
        </inertial>

    </link>
    <link name="right_finger">
        <visual>
            <origin rpy="0 0 0" xyz="0 0 0" />
            <geometry>
                <mesh filename="package://fanuc_lrmate200id_support/meshes/lrmate200id/visual/right_finger.stl" scale="0.001 0.001 0.001" />
            </geometry>
            <material name="">
                <color rgba="0.75 0.75 0.75 1.0" />
            </material>
        </visual>
        <collision>
            <origin rpy="0 0 0" xyz="0 0 0" />
            <geometry>
                <mesh filename="package://fanuc_lrmate200id_support/meshes/lrmate200id/collision/right_finger.stl" scale="0.001 0.001 0.001" />
            </geometry>
        </collision>
        
<inertial>
            <mass value="0.01" />
            <origin rpy="0 0 0" xyz="0 0 0" />
            <inertia ixx="6e-06" ixy="0" ixz="0" iyy="6e-06" iyz="0" izz="6e-06" />
        </inertial>

    </link>
    <!-- joints: main serial chain -->
    <joint name="joint_1" type="revolute">
        <origin rpy="0 0 0" xyz="-0.006 -0.002 0.290" />
        <parent link="base_link" />
        <child link="link_1" />
        <axis xyz="0 0 1" />
        <dynamics damping="1.0" />
        <limit effort="100" lower="-2.965" upper="2.965" velocity="7.85" />
    </joint>
    <joint name="joint_2" type="revolute">
        <origin rpy="0 0 0" xyz="0 0 0.040" />
        <parent link="link_1" />
        <child link="link_2" />
        <axis xyz="0 1 0" />
        <dynamics damping="1.0" />
        <limit effort="100" lower="-1.745329" upper="2.530727" velocity="6.63" />
    </joint>
    <joint name="joint_3" type="revolute">
        <origin rpy="0 0 0" xyz="0.0 0 0.26" />
        <parent link="link_2" />
        <child link="link_3" />
        <axis xyz="0 -1 0" />
        <dynamics damping="1.0" />
        <limit effort="100" lower="-2.450966" upper="4.886922" velocity="9.08" />
    </joint>
    <joint name="joint_4" type="revolute">
        <origin rpy="0 0 0" xyz="0.064 0 0.02" />
        <parent link="link_3" />
        <child link="link_4" />
        <axis xyz="-1 0 0" />
        <dynamics damping="1.0" />
        <limit effort="100" lower="-3.315" upper="3.315" velocity="9.60" />
    </joint>
    <joint name="joint_5" type="revolute">
        <origin rpy="0 0 0" xyz="0.226 0 0" />
        <parent link="link_4" />
        <child link="link_5" />
        <axis xyz="0 -1 0" />
        <dynamics damping="1.0" />
        <limit effort="100" lower="-2.18" upper="2.18" velocity="9.51" />
    </joint>
    <joint name="joint_6" type="revolute">
        <origin rpy="0 0 0" xyz="0.070 0 0" />
        <parent link="link_5" />
        <child link="link_6" />
        <axis xyz="-1 0 0" />
        <dynamics damping="1.0" />
        <limit effort="100" lower="-6.285" upper="6.285" velocity="17.45" />
    </joint>
    <!-- WORLD LINK -->
    <link name="world" />
    <joint name="world" type="fixed">
        <origin rpy="0 0 0" xyz="0 0 0" />
        <parent link="world" />
        <child link="base_link" />
    </joint>
    <!-- ROS-Industrial 'flange' frame: attachment point for EEF models -->
    <joint name="joint_6-flange" type="fixed">
        <origin rpy="0 0 0" xyz="0.0 0.0 0.0" />
        <parent link="link_6" />
        <child link="flange" />
    </joint>
    <joint name="finger_joint1" type="prismatic">
        <parent link="flange" />
        <child link="left_finger" />
        <origin rpy="0 0 0" xyz="0.088 0 0" />
        <axis xyz="0 -1 0" />
        <dynamics damping="1.0" />
        <limit effort="10" lower="0.0" upper="0.015" velocity="0.2" />
    </joint>
    <joint name="finger_joint2" type="prismatic">
        <parent link="flange" />
        <child link="right_finger" />
        <origin rpy="0 0 0" xyz="0.088 0 0" />
        <axis xyz="0 1 0" />
        <dynamics damping="1.0" />
        <limit effort="10" lower="0.0" upper="0.015" velocity="0.2" />
        <mimic joint="finger_joint1" />
    </joint>
    <!-- MATERIALS GAZEBO -->
    <gazebo reference="base_link">
        <material>Gazebo/Grey</material>
    </gazebo>
    <gazebo reference="link_1">
        <material>Gazebo/Yellow</material>
    </gazebo>
    <gazebo reference="link_2">
        <material>Gazebo/Yellow</material>
    </gazebo>
    <gazebo reference="link_3">
        <material>Gazebo/Yellow</material>
    </gazebo>
    <gazebo reference="link_4">
        <material>Gazebo/Yellow</material>
    </gazebo>
    <gazebo reference="link_5">
        <material>Gazebo/Yellow</material>
    </gazebo>
    <gazebo reference="link_6">
        <material>Gazebo/Grey</material>
    </gazebo>
    <gazebo reference="{prefix}link1">
        <mu1>0.61</mu1>
        <mu2>0.61</mu2>
    </gazebo>
    <gazebo reference="{prefix}link2">
        <mu1>0.61</mu1>
        <mu2>0.61</mu2>
    </gazebo>
    <gazebo reference="{prefix}link3">
        <mu1>0.61</mu1>
        <mu2>0.61</mu2>
    </gazebo>
    <gazebo reference="{prefix}link4">
        <mu1>0.61</mu1>
        <mu2>0.61</mu2>
    </gazebo>
    <gazebo reference="{prefix}link5">
        <mu1>0.61</mu1>
        <mu2>0.61</mu2>
    </gazebo>
    <gazebo reference="{prefix}link6">
        <mu1>0.61</mu1>
        <mu2>0.61</mu2>
    </gazebo>
    <gazebo reference="{prefix}left_finger">
        <mu1>1.00</mu1>
        <mu2>1.00</mu2>
    </gazebo>
    <gazebo reference="{prefix}right_finger">
        <mu1>1.00</mu1>
        <mu2>1.00</mu2>
    </gazebo>
    
<transmission name="trans_joint_1">
        <type>transmission_interface/SimpleTransmission</type>
        <joint name="joint_1">
            <hardwareInterface>hardware_interface/PositionJointInterface</hardwareInterface>
        </joint>
        <actuator name="joint_1_motor">
            <hardwareInterface>hardware_interface/PositionJointInterface</hardwareInterface>
            <mechanicalReduction>1</mechanicalReduction>
        </actuator>
    </transmission>
    <transmission name="trans_joint_2">
        <type>transmission_interface/SimpleTransmission</type>
        <joint name="joint_2">
            <hardwareInterface>hardware_interface/PositionJointInterface</hardwareInterface>
        </joint>
        <actuator name="joint_2_motor">
            <hardwareInterface>hardware_interface/PositionJointInterface</hardwareInterface>
            <mechanicalReduction>1</mechanicalReduction>
        </actuator>
    </transmission>
    <transmission name="trans_joint_3">
        <type>transmission_interface/SimpleTransmission</type>
        <joint name="joint_3">
            <hardwareInterface>hardware_interface/PositionJointInterface</hardwareInterface>
        </joint>
        <actuator name="joint_3_motor">
            <hardwareInterface>hardware_interface/PositionJointInterface</hardwareInterface>
            <mechanicalReduction>1</mechanicalReduction>
        </actuator>
    </transmission>
    <transmission name="trans_joint_4">
        <type>transmission_interface/SimpleTransmission</type>
        <joint name="joint_4">
            <hardwareInterface>hardware_interface/PositionJointInterface</hardwareInterface>
        </joint>
        <actuator name="joint_4_motor">
            <hardwareInterface>hardware_interface/PositionJointInterface</hardwareInterface>
            <mechanicalReduction>1</mechanicalReduction>
        </actuator>
    </transmission>
    <transmission name="trans_joint_5">
        <type>transmission_interface/SimpleTransmission</type>
        <joint name="joint_5">
            <hardwareInterface>hardware_interface/PositionJointInterface</hardwareInterface>
        </joint>
        <actuator name="joint_5_motor">
            <hardwareInterface>hardware_interface/PositionJointInterface</hardwareInterface>
            <mechanicalReduction>1</mechanicalReduction>
        </actuator>
    </transmission>
    <transmission name="trans_joint_6">
        <type>transmission_interface/SimpleTransmission</type>
        <joint name="joint_6">
            <hardwareInterface>hardware_interface/PositionJointInterface</hardwareInterface>
        </joint>
        <actuator name="joint_6_motor">
            <hardwareInterface>hardware_interface/PositionJointInterface</hardwareInterface>
            <mechanicalReduction>1</mechanicalReduction>
        </actuator>
    </transmission>
    <transmission name="trans_finger_joint1">
        <type>transmission_interface/SimpleTransmission</type>
        <joint name="finger_joint1">
            <hardwareInterface>hardware_interface/EffortJointInterface</hardwareInterface>
        </joint>
        <actuator name="finger_joint1_motor">
            <hardwareInterface>hardware_interface/EffortJointInterface</hardwareInterface>
            <mechanicalReduction>1</mechanicalReduction>
        </actuator>
    </transmission>
    <transmission name="trans_finger_joint2">
        <type>transmission_interface/SimpleTransmission</type>
        <joint name="finger_joint2">
            <hardwareInterface>hardware_interface/EffortJointInterface</hardwareInterface>
        </joint>
        <actuator name="finger_joint2_motor">
            <hardwareInterface>hardware_interface/EffortJointInterface</hardwareInterface>
            <mechanicalReduction>1</mechanicalReduction>
        </actuator>
    </transmission>
    <gazebo>
        <plugin name="gazebo_ros_control" filename="libgazebo_ros_control.so">
            <robotNamespace>/</robotNamespace>
        </plugin>
    </gazebo>
</robot>