<?xml version="1.0"?>
<robot name="myfirst">
  <link name="base_link">
    <visual>
      <origin rpy="0 0 0" xyz="0 0 0.75" />
      <geometry>
        <box size="0.5 0.5 1.5"/> 
      </geometry>
    </visual>
  </link>
  <link name="link_one">
    <visual>
      <origin rpy="0 0 0" xyz="0 0 0.75" />
      <geometry>
        <box size="0.5 0.5 1.5"/> 
      </geometry>
      <material name="white"/>
    </visual>
  </link>
  <joint name="base_to_one" type="revolute">
    <parent link="base_link"/>
    <child link="link_one"/>
    <axis xyz="0.0 1.0 0.0"/>
    <origin xyz="0.0 0.0 1.5" />
    <limit lower="-1.0" upper="1.0" effort="1000.0" velocity="0.5"/>
  </joint>
  <!-- <joint name="base_to_one" type="fixed">
    <parent link="base_link"/>
    <child link="link_one"/>
    <origin xyz="0.0 0.0 1.5" />
  </joint> -->
</robot>