<?xml version="1.0" encoding="utf-8"?>
<!-- =================================================================================== -->
<!-- |    This document was autogenerated by xacro from ./src/urdf_exercise/urdf/two_links.xacro | -->
<!-- |    EDITING THIS FILE BY HAND IS NOT RECOMMENDED                                 | -->
<!-- =================================================================================== -->
<robot name="two_links_robot">
  <link name="base_link">
    <visual>
      <origin rpy="0 0 0" xyz="0 0 0.75"/>
      <geometry>
        <box size="0.5 0.5 1.5"/>
      </geometry>
    </visual>
  </link>
  <link name="link_one">
    <visual>
      <origin rpy="0 0 0" xyz="0 0 0.75"/>
      <geometry>
        <box size="0.5 0.5 1.5"/>
      </geometry>
      <material name="white"/>
    </visual>
  </link>
  <joint name="connection_joint" type="revolute">
    <parent link="base_link"/>
    <child link="link_one"/>
    <origin xyz="0.0 0.0 1.5"/>
    <limit effort="1000.0" lower="-1.0" upper="1.0" velocity="0.5"/>
  </joint>
</robot>

